<mujoco model="solo">
    <compiler angle="radian" />
    <size njmax="500" nconmax="100" />
    <asset>
        <mesh name="solo_body" file="solo_body.stl" />
        <mesh name="solo_upper_leg_left_side" file="solo_upper_leg_left_side.stl" />
        <mesh name="solo_lower_leg_left_side" file="solo_lower_leg_left_side.stl" />
        <mesh name="solo_foot" file="solo_foot.stl" />
        <mesh name="solo_upper_leg_right_side" file="solo_upper_leg_right_side.stl" />
        <mesh name="solo_lower_leg_right_side" file="solo_lower_leg_right_side.stl" />
    </asset>
    <worldbody>
        <geom type="mesh" contype="0" conaffinity="0" group="1" rgba="0.8 0.8 0.8 1" mesh="solo_body" />
        <geom type="mesh" rgba="0.8 0.8 0.8 1" mesh="solo_body" />
        <body name="FL_UPPER_LEG" pos="0.19 0.1046 0">
            <inertial pos="1.377e-05 0.0193585 -0.078707" quat="0.705834 0.0424071 -0.0424071 0.705834" mass="0.148538" diaginertia="0.000417563 0.00041107 2.46069e-05" />
            <joint name="FL_HFE" pos="0 0 0" axis="0 1 0" limited="true" range="-10 10" />
            <geom type="mesh" contype="0" conaffinity="0" group="1" rgba="0.8 0.8 0.8 1" mesh="solo_upper_leg_left_side" />
            <geom type="mesh" rgba="0.8 0.8 0.8 1" mesh="solo_upper_leg_left_side" />
            <body name="FL_LOWER_LEG" pos="0 0.03745 -0.16">
                <inertial pos="0 0.00789921 -0.102249" quat="0.707067 0.00747737 -0.00747737 0.707067" mass="0.0376361" diaginertia="0.000149205 0.000148819 2.62453e-06" />
                <joint name="FL_KFE" pos="0 0 0" axis="0 1 0" limited="true" range="-10 10" />
                <geom type="mesh" contype="0" conaffinity="0" group="1" rgba="0.8 0.8 0.8 1" mesh="solo_lower_leg_left_side" />
                <geom type="mesh" rgba="0.8 0.8 0.8 1" mesh="solo_lower_leg_left_side" />
                <geom pos="0 0.008 -0.16" type="mesh" contype="0" conaffinity="0" group="1" rgba="0.8 0.8 0.8 1" mesh="solo_foot" />
                <geom pos="0 0.008 -0.16" type="mesh" rgba="0.8 0.8 0.8 1" mesh="solo_foot" />
            </body>
        </body>
        <body name="FR_UPPER_LEG" pos="0.19 -0.1046 0">
            <inertial pos="-1.377e-05 -0.0193585 -0.078707" quat="0.705834 -0.0424071 0.0424071 0.705834" mass="0.148538" diaginertia="0.000417563 0.00041107 2.46069e-05" />
            <joint name="FR_HFE" pos="0 0 0" axis="0 1 0" limited="true" range="-10 10" />
            <geom type="mesh" contype="0" conaffinity="0" group="1" rgba="0.8 0.8 0.8 1" mesh="solo_upper_leg_right_side" />
            <geom type="mesh" rgba="0.8 0.8 0.8 1" mesh="solo_upper_leg_right_side" />
            <body name="FR_LOWER_LEG" pos="0 -0.03745 -0.16">
                <inertial pos="0 0.00495053 -0.102249" quat="0.999484 -0.0321221 0 0" mass="0.0376361" diaginertia="0.000150245 0.000149742 3.5132e-06" />
                <joint name="FR_KFE" pos="0 0 0" axis="0 1 0" limited="true" range="-10 10" />
                <geom type="mesh" contype="0" conaffinity="0" group="1" rgba="0.8 0.8 0.8 1" mesh="solo_lower_leg_right_side" />
                <geom type="mesh" rgba="0.8 0.8 0.8 1" mesh="solo_lower_leg_right_side" />
                <geom pos="0 -0.008 -0.16" type="mesh" contype="0" conaffinity="0" group="1" rgba="0.8 0.8 0.8 1" mesh="solo_foot" />
                <geom pos="0 -0.008 -0.16" type="mesh" rgba="0.8 0.8 0.8 1" mesh="solo_foot" />
            </body>
        </body>
        <body name="HL_UPPER_LEG" pos="-0.19 0.1046 0">
            <inertial pos="1.377e-05 0.0193585 -0.078707" quat="0.705834 0.0424071 -0.0424071 0.705834" mass="0.148538" diaginertia="0.000417563 0.00041107 2.46069e-05" />
            <joint name="HL_HFE" pos="0 0 0" axis="0 1 0" limited="true" range="-10 10" />
            <geom type="mesh" contype="0" conaffinity="0" group="1" rgba="0.8 0.8 0.8 1" mesh="solo_upper_leg_left_side" />
            <geom type="mesh" rgba="0.8 0.8 0.8 1" mesh="solo_upper_leg_left_side" />
            <body name="HL_LOWER_LEG" pos="0 0.03745 -0.16">
                <inertial pos="0 0.00789921 -0.102249" quat="0.707067 0.00747737 -0.00747737 0.707067" mass="0.0376361" diaginertia="0.000149205 0.000148819 2.62453e-06" />
                <joint name="HL_KFE" pos="0 0 0" axis="0 1 0" limited="true" range="-10 10" />
                <geom type="mesh" contype="0" conaffinity="0" group="1" rgba="0.8 0.8 0.8 1" mesh="solo_lower_leg_left_side" />
                <geom type="mesh" rgba="0.8 0.8 0.8 1" mesh="solo_lower_leg_left_side" />
                <geom pos="0 0.008 -0.16" type="mesh" contype="0" conaffinity="0" group="1" rgba="0.8 0.8 0.8 1" mesh="solo_foot" />
                <geom pos="0 0.008 -0.16" type="mesh" rgba="0.8 0.8 0.8 1" mesh="solo_foot" />
            </body>
        </body>
        <body name="HR_UPPER_LEG" pos="-0.19 -0.1046 0">
            <inertial pos="-1.377e-05 -0.0193585 -0.078707" quat="0.705834 -0.0424071 0.0424071 0.705834" mass="0.148538" diaginertia="0.000417563 0.00041107 2.46069e-05" />
            <joint name="HR_HFE" pos="0 0 0" axis="0 1 0" limited="true" range="-10 10" />
            <geom type="mesh" contype="0" conaffinity="0" group="1" rgba="0.8 0.8 0.8 1" mesh="solo_upper_leg_right_side" />
            <geom type="mesh" rgba="0.8 0.8 0.8 1" mesh="solo_upper_leg_right_side" />
            <body name="HR_LOWER_LEG" pos="0 -0.03745 -0.16">
                <inertial pos="0 0.00495053 -0.102249" quat="0.999484 -0.0321221 0 0" mass="0.0376361" diaginertia="0.000150245 0.000149742 3.5132e-06" />
                <joint name="HR_KFE" pos="0 0 0" axis="0 1 0" limited="true" range="-10 10" />
                <geom type="mesh" contype="0" conaffinity="0" group="1" rgba="0.8 0.8 0.8 1" mesh="solo_lower_leg_right_side" />
                <geom type="mesh" rgba="0.8 0.8 0.8 1" mesh="solo_lower_leg_right_side" />
                <geom pos="0 -0.008 -0.16" type="mesh" contype="0" conaffinity="0" group="1" rgba="0.8 0.8 0.8 1" mesh="solo_foot" />
                <geom pos="0 -0.008 -0.16" type="mesh" rgba="0.8 0.8 0.8 1" mesh="solo_foot" />
            </body>
        </body>
    </worldbody>
    <actuator>
        <motor ctrllimited="true" ctrlrange="-10 10" joint="FL_HFE" gear="150"/>
        <motor ctrllimited="true" ctrlrange="-10 10" joint="FL_KFE" gear="150"/>
        <motor ctrllimited="true" ctrlrange="-10 10" joint="FR_HFE" gear="150"/>
        <motor ctrllimited="true" ctrlrange="-10 10" joint="FR_KFE" gear="150"/>
        <motor ctrllimited="true" ctrlrange="-10 10" joint="HL_HFE" gear="150"/>
        <motor ctrllimited="true" ctrlrange="-10 10" joint="HL_KFE" gear="150"/>
        <motor ctrllimited="true" ctrlrange="-10 10" joint="HR_HFE" gear="150"/>
        <motor ctrllimited="true" ctrlrange="-10 10" joint="HR_KFE" gear="150"/>
    </actuator>
</mujoco>
